Workbook

Sheet All (Office Wise)
A2: ক্রমিক নং | B2: দপ্তরের নাম | C2: নিরীক্ষা বছর | D2: অনু নং | E2: আপত্তির শিরোনাম | F2: জড়িত টাকার পরিমান | G2: আপত্তির ধরণ | H2: ক্যাটাগরী | I2: জোন
A3: 1 | B3: আঞ্চলিক পূর্ত নির্মাণ বিভাগ, বিউবো, ময়মনসিংহ | C3: ২০২১-২০২২ | D3: 45.7 | E3: একই ধরনের কাজকে একাধিক প্যাকেজে বিভক্ত করে এলটিম এর মাধ্যমে সম্পাদন করে অনিয়মিতভাবে ২,৬৭,১৪,০২০/- টাকার কার্যসম্পাদন | F3: 21714020 | G3: এসএফআই | H3: আর্থিক বিধি অনুসরণ না করা | I3: ময়মনসিংহ
A4: 2 | B4: আঞ্চলিক পূর্ত নির্মাণ বিভাগ, বিউবো, ময়মনসিংহ | C4: ২০২২-২০২৩ | D4: 47.7 | E4: অর্থ বিভাগের ব্যয় সংকোচনের নির্দেশনা লঙ্ঘন কওে নির্ধারিত ব্যয়সীমার অতিরিক্ত ব্যয় | F4: 702610 | G4: এসএফআই | H4: আর্থিক বিধি অনুসরণ না করা | I4: ময়মনসিংহ
A5: 3 | B5: আঞ্চলিক পূর্ত নির্মাণ বিভাগ, বিউবো, ময়মনসিংহ | C5: ২০২৩ - ২০২৪ | D5: 46.2 | E5: দরপত্র প্রণয়নে এসটিডি’র নির্ধারিত হার অপেক্ষা অতিরিক্ত হারে বার্ষিক টার্ণওভার নির্ধারণ করে চুক্তি সম্পাদনের মাধ্যমে অনিয়মিত ব্যয় ৪,৪৬,৯০,০১১ টাকা। | F5: ৪,৪৬,৯০,০১১/- | G5: এসএফআই | H5: টেন্ডার ও ক্রয় | I5: ময়মনসিংহ
A6: 4 | B6: আঞ্চলিক পূর্ত নির্মাণ বিভাগ, বিউবো, ময়মনসিংহ | C6: ২০২৩ - ২০২৪ | D6: 45.2 | E6: উর্ধতন কর্তৃপক্ষের অনুমোদনের বাধ্যবাধকতা এড়ানোর উদ্দেশ্যে একই ধরণের কাজকে একাধিক খন্ডে বিভাক্ত চুক্তি সম্পাদনে ১৬,৫৭,৮৯৪/- টাকা অনিয়মিত ব্যয়। | F6: ১৬,৫৭,৮৯৪/- | G6: এসএফআই | H6: টেন্ডার ও ক্রয় | I6: ময়মনসিংহ
A7: 5 | B7: আঞ্চলিক পূর্ত নির্মাণ বিভাগ, বিউবো, ময়মনসিংহ | C7: ২০২৩ - ২০২৪ | D7: 42.3 | E7: দাপ্তরিক প্রাক্কলিত মূল্যের চেয়ে অধিক নিম্নদরে দাখিলকৃত দরদাতার সাথে চুক্তিসম্পাদন করায় ফলে অনিয়মিত ব্যয় ৮,৩৬,৮২৫ (আট লক্ষ ছত্রিশ হাজার আটশত পঁচিশ) টাকা। | F7: ৮,৩৬,৮২৫/- | G7: এসএফআই | H7: টেন্ডার ও ক্রয় | I7: ময়মনসিংহ
A8: 6 | B8: আঞ্চলিক পূর্ত নির্মাণ বিভাগ, বিউবো, ময়মনসিংহ | C8: ২০২৩ - ২০২৪ | D8: 34 | E8: দরপত্রের শর্তানুসারে যথাযথ অভিজ্ঞতার সনদ না থাকা সত্ত্বেও নন-রেসপনসিভযোগ্য দরদাতাকে রেসপনসিভ করে চুক্তি সম্পাদনে অনিয়মিত ব্যয় ২৩,২০,২০৮ (তেইশ লক্ষ বিশ হাজার দুইশত আট) টাকা। | F8: ২৩,২০,২০৮/- | G8: এসএফআই | H8: টেন্ডার ও ক্রয় | I8: ময়মনসিংহ
A9: 7 | B9: আবাসিক প্রকৌশলী, ঈশ্বরগঞ্জ বিদ্যুৎ সরবরাহ, বিউবো, ময়মনসিংহ | C9: ১৯৯০-১৯৯৪ | D9: 3 | E9: মৃত হিসাবধারী গ্রাহকের নিকট ৬,৩৫,৬৮৯/- টাকা । | F9: 635689 | G9: এসএফআই | H9: বিদ্যুৎ বিল বকেয়া | I9: ময়মনসিংহ
A10: 8 | B10: আবাসিক প্রকৌশলী, গৌরীপুর বিদ্যুৎ সরবরাহ, বিউবেো, ময়মনসিংহ | C10: ১৯৯৬-২০০০ | D10: 3 | E10: ডেড একাউন্টের ৬৭ জন গ্রাহকের নিকট হইতে অনাদায়ী ৩,৭৭,৭২৬/- টাকার বিষয়ে বাস্তব ব্যবস্থা গ্রহণ করা প্রয়োজন। | F10: 377726 | G10: এসএফআই | H10: বিদ্যুৎ বিল বকেয়া | I10: ময়মনসিংহ
A11: 9 | B11: প্রকল্প পরিচালক, বিদ্যুৎ বিতরণ ব্যবস্থা উন্নয়ন প্রকল্প, ময়মনসিংহ | C11: ২০১৯-২০২০ | D11: 9 | E11: প্রকল্পের যানবাহন ক্রয়কাজে পিপিআর ২০০৮ এ বিধি লংঘন করে অফিসিয়াল কস্ট ইস্টিমেট প্রস্তত ছাড়াই এবং অর্থ মন্ত্রণালয়ের নির্ধরিত মূল্য ও ডিপিপির বরাদ্দ হতে হারে অনিয়মিতভাবে দরপত্র আহব্বানপূর্বক১,৯৫,৯৮,০০৪/- টাকা অর্থ পরিশোধ । | F11: 19598004 | G11: এসএফআই | H11: আর্থিক বিধি অনুসরণ না করা | I11: ময়মনসিংহ
A12: 10 | B12: প্রকল্প পরিচালক, বিদ্যুৎ বিতরণ ব্যবস্থা উন্নয়ন প্রকল্প, ময়মনসিংহ | C12: ২০১৯-২০২০ | D12: 10 | E12: ডিপিপির নির্দেশনা লংঘন করে পুর্ত নির্মন কাজে বাজেট বরাদ্দ ছাড়াই একক কাজকে দুইটি ভাগে বিভক্ত করে বিশেষায়িত প্রকৃতির কাজ না হওয়া সত্তে¡ও সমিত দরপত্র পদ্ধতিতে সমদরে ও একই দিনে পছন্দের একমাত্র ঠিকাদারকে ২৭,৮৫,৫০২/- টাকা পরিশোধ । | F12: 2785502 | G12: এসএফআই | H12: আর্থিক বিধি অনুসরণ না করা | I12: ময়মনসিংহ
A13: 11 | B13: প্রকল্প পরিচালক, বিদ্যুৎ বিতরণ ব্যবস্থা উন্নয়ন প্রকল্প, ময়মনসিংহ | C13: ২০২০-২০২১ | D13: 2(2) | E13: অর্থ মন্ত্রণালয়ের আদেশের ব্যত্রয় করে ভুমি অধিগ্রহনে জমির মূল্যের সাথে 2 থেকে 7.5% পর্যন্ত ব্যয় পরিশোধ | F13: 5779446 | G13: এসএফআই | H13: আর্থিক বিধি অনুসরণ না করা | I13: ময়মনসিংহ
A14: 12 | B14: প্রকল্প পরিচালক, বিদ্যুৎ বিতরণ ব্যবস্থা উন্নয়ন প্রকল্প, ময়মনসিংহ | C14: ২০২০-২০২১ | D14: 18 | E14: ডিপিবির ক্রয় পক্রিয়া অনুযায়ী ক্রয়কার্য সম্পাদন না করে ডিপিবির প্যাকেজের লট কমিয়ে ক্রয়কায় সম্পাদন করে অতিরিক্ত ব্যয় ১৭৭,৫৫৮,১৫০/- | F14: 177558150 | G14: এসএফআই | H14: আর্থিক বিধি অনুসরণ না করা | I14: ময়মনসিংহ
A15: 13 | B15: প্রকল্প পরিচালক, বিদ্যুৎ বিতরণ ব্যবস্থা উন্নয়ন প্রকল্প, ময়মনসিংহ | C15: ২০২০-২০২১ | D15: 24(1) | E15: কর্মকর্তাগনকে ভ্রমনভাতা বিল পরিশোধের ক্ষেত্রে বিধি বহির্ভূত দৈনিকভাতা প্রদান | F15: 197874 | G15: নন-এসএফআই | H15: বেতন-ভাতা সংক্রান্ত | I15: ময়মনসিংহ
A16: 14 | B16: প্রকল্প পরিচালক, বিদ্যুৎ বিতরণ ব্যবস্থা উন্নয়ন প্রকল্প, ময়মনসিংহ | C16: ২০২০-২০২১ | D16: 30(1) | E16: প্রাপ্যের অতিরিক্ত গাঢ়িতে জ্বালানী তেল ব্যবহার করায় ক্ষতি | F16: 633230 | G16: নন-এসএফআই | H16: বিবিধ | I16: ময়মনসিংহ
A17: 15 | B17: প্রকল্প পরিচালক, বিদ্যুৎ বিতরণ ব্যবস্থা উন্নয়ন প্রকল্প, ময়মনসিংহ | C17: ২০২১-২০২২ | D17: 41 | E17: অনিয়মিতভাবে মূল বেতনের অতিরিক্ত অধিকালভাতা প্রদাণ করায় প্রতিষ্ঠানের আর্থিক ক্ষতি ৪৮৩০৫৪/- | F17: 483054 | G17: এসএফআই | H17: অধিকাল ভাতা | I17: ময়মনসিংহ
A18: 16 | B18: প্রকল্প পরিচালক, বিদ্যুৎ বিতরণ ব্যবস্থা উন্নয়ন প্রকল্প, ময়মনসিংহ | C18: ২০২১-২০২২ | D18: 43 | E18: অর্থ মন্ত্রনালয়ের আদেশের ব্যতয় করে ভ‚মি অধিগ্রহনের জমির মূল্যের সাথে৭.৫% এবং ২% হারে আনুষাঙ্গিক ব্যয পরিশোধ করায় সংস্থার আর্থিক ক্ষতি ৩৮১৮৩৭১/- টাকা । | F18: 3818371 | G18: এসএফআই | H18: আর্থিক বিধি অনুসরণ না করা | I18: ময়মনসিংহ
A19: 17 | B19: প্রকল্প পরিচালক, বিদ্যুৎ বিতরণ ব্যবস্থা উন্নয়ন প্রকল্প, ময়মনসিংহ | C19: ২০২১-২০২২ | D19: 34 | E19: ঠিকাদার কর্তৃক বিভিন্ন চুক্তির বিপরীতে বীমা না করায় বীমা প্রিমিয়ামের উপর ভ্যাট বাবদ সরকারের রাজস্ব ক্ষতি ৫২৫৭৬২ | F19: 525762 | G19: এসএফআই | H19: ভ্যাট ও আয়কর (সরকারি) | I19: ময়মনসিংহ
A20: 18 | B20: প্রকল্প পরিচালক, বিদ্যুৎ বিতরণ ব্যবস্থা উন্নয়ন প্রকল্প, ময়মনসিংহ | C20: ২০২২-২০২৩ | D20: 8 | E20: দরপত্রের বৈধতার মেয়াদ অতিক্রান্ত হওয়ার পর সরবরাহকারীর সাথে অবৈধভাবে চুক্তি সম্পাদন | F20: 281052029 | G20: এসএফআই | H20: আর্থিক বিধি অনুসরণ না করা | I20: ময়মনসিংহ
A21: 19 | B21: প্রকল্প পরিচালক, বিদ্যুৎ বিতরণ ব্যবস্থা উন্নয়ন প্রকল্প, ময়মনসিংহ | C21: ২০২২-২০২৩ | D21: 10 | E21: প্রতিযোগীতা না হওয়া সত্তেও দরপত্র বাতিল না কওে দাপ্তরিক প্রাক্কলিত মূল্যোর উর্ধ্ধদওে ঠিকাদার/ সরবরাহকারীর সাথে চুক্তি সম্পাদন করায় আর্থিক ক্ষতি | F21: 1567887 | G21: এসএফআই | H21: আর্থিক বিধি অনুসরণ না করা | I21: ময়মনসিংহ
A22: 20 | B22: প্রকল্প পরিচালক, বিদ্যুৎ বিতরণ ব্যবস্থা উন্নয়ন প্রকল্প, ময়মনসিংহ | C22: ২০২২-২০২৩ | D22: 21 | E22: দাপ্তরিক প্রাক্কলিত মূল্য পুনঃ পরীক্ষা এবং কম মূল্য উদ্ধৃত করার কারণ অনুসন্ধান না কওে অস্বাভাবিক নি¤œদওে কার্যাদেশ প্রান করায় অনিয়মিত ব্যয় | F22: 10926802 | G22: এসএফআই | H22: আর্থিক বিধি অনুসরণ না করা | I22: ময়মনসিংহ
A23: 21 | B23: প্রকল্প পরিচালক, বিদ্যুৎ বিতরণ ব্যবস্থা উন্নয়ন প্রকল্প, ময়মনসিংহ | C23: ২০২২-২০২৩ | D23: 36 | E23: নিম্ন দরের দরদাতা কারিগরিভাবে রেসপনসিভ হওয়া সত্ত্বেও উর্ধ্বদরের দরদাতার সহিত অনিয়মিতভাবে চুক্তি সম্পাদনের মাধ্যমে অতিরিক্ত ব্যায় । | F23: 16486500 | G23: এসএফআই | H23: আর্থিক বিধি অনুসরণ না করা | I23: ময়মনসিংহ
A24: 22 | B24: প্রকল্প পরিচালক, বিদ্যুৎ বিতরণ ব্যবস্থা উন্নয়ন প্রকল্প, ময়মনসিংহ | C24: ২০২২-২০২৩ | D24: 78 | E24: নির্ধারিত সময়ে কার্য সম্পাদনে ব্যর্থ ঠিকাদারের নিকট হতে আরোপযোগ্য বিলম্ব জরিমানা আদায় না করায় পতিষ্ঠানের আর্থিক ক্ষতি | F24: 2644070 | G24: নন-এসএফআই | H24: আর্থিক বিধি অনুসরণ না করা | I24: ময়মনসিংহ
A25: 23 | B25: প্রকল্প পরিচালক, বিদ্যুৎ বিতরণ ব্যবস্থা উন্নয়ন প্রকল্প, ময়মনসিংহ | C25: ২০২৩ - ২০২৪ | D25: 41.1 | E25: দাপ্তরিক প্রাক্কলিত মূল্যের চেয়ে অস্বাভাবিক ঊর্ধ্বদরে দাখিলকৃত দরদাতার সাথে অনিয়মিতভাবে ৮৪৭০০০০০ (আট কোটি সাতচল্লিশ লক্ষ) টাকার কার্য সম্পাদন। | F25: ৮,৪৭,০০,০০০/- | G25: এসএফআই | H25: টেন্ডার ও ক্রয় | I25: ময়মনসিংহ
A26: 24 | B26: প্রকল্প পরিচালক, বিদ্যুৎ বিতরণ ব্যবস্থা উন্নয়ন প্রকল্প, ময়মনসিংহ | C26: ২০২৩ - ২০২৪ | D26: 59 | E26: পণ্য ও সংশ্লিষ্ট সেবাকে পূর্ত কাজ দেখিয়ে চুক্তি সম্পাদন করায় ৮৯,৯৮,০৩৭ (উননব্বই লক্ষ আটানব্বই হাজার সাইত্রিশ) টাকার অনিয়মিত ব্যয় । | F26: ৮৯,৯৮,০৩৭/- | G26: এসএফআই | H26: টেন্ডার ও ক্রয় | I26: ময়মনসিংহ
A27: 25 | B27: প্রকল্প পরিচালক, বিদ্যুৎ বিতরণ ব্যবস্থা উন্নয়ন প্রকল্প, ময়মনসিংহ | C27: ২০২৩ - ২০২৪ | D27: 48 | E27: পিপিআর মোতাবেক নির্ধারিত সময়ে চুক্তি সম্পাদনে ব্যর্থতা সত্বেও দরপত্র জামানত বাজেয়াপ্ত না করে অনিয়মিতভাবে ৫৪,০৫,৫৬,৯২৩ (চুয়ান্ন কোটি পাঁচ লক্ষ ছাপান্ন হাজার নয়শত তেইশ) টাকার চুক্তি সম্পাদন। | F27: ৫৪,০৫,৫৬,৯২৩/- | G27: এসএফআই | H27: টেন্ডার ও ক্রয় | I27: ময়মনসিংহ
A28: 26 | B28: বিক্রয় ও বিতরণ বিভাগ -ত্রিশাল, বিউবো, ময়মনসিংহ | C28: ২০২১-২০২২ | D28: 28 | E28: বিভিন্ন শ্রেনীর গ্রাহকের নিকট হতে বকেয় বিদ্যুৎ বিল আদায় না করায় প্রতিষ্ঠানের আর্থিক ক্ষতি৩৫৭৫২৯২/- টাকা | F28: 3575292 | G28: এসএফআই | H28: বিদ্যুৎ বিল বকেয়া | I28: ময়মনসিংহ
A29: 27 | B29: বিক্রয় ও বিতরণ বিভাগ -ভালুকা, বিউবো, ময়মনসিংহ | C29: ২০২১-২০২২ | D29: 73.3 | E29: প্রাকযোগ্যতা যথাযথভাবে যাচাই ব্যতিরেকে ঠিকাদারকে কার্যাদেশ প্রদানে প্রতিষ্ঠানের অনিয়মিত ব্যয় ১১,৯৬,৯৬৫/--টাকা | F29: 1196965 | G29: নন-এসএফআই | H29: আর্থিক বিধি অনুসরণ না করা | I29: ময়মনসিংহ
A30: 28 | B30: বিক্রয় ও বিতরণ বিভাগ, কিশোরগঞ্জ | C30: ২০১০-২০১১ | D30: 3 | E30: বেসরকারি ব্যক্তি প্রতিষ্ঠানের নিকট হতে উর্দ্ধতন কর্তৃপক্ষের নির্ধারিত টার্গেট মোতাবেক বকেয়া আদায়ে ব্যর্থতায় ক্ষতি | F30: 60204902 | G30: নন-এসএফআই | H30: বিদ্যুৎ বিল বকেয়া | I30: ময়মনসিংহ
A31: 29 | B31: বিক্রয় ও বিতরণ বিভাগ, কিশোরগঞ্জ | C31: ২০২২-২০২৩ | D31: 51 | E31: মন্ত্রণালয়ের নির্দেশ উপেক্ষা কওে সোলার প্যানেল স্থাপন না করা সত্তে¡ও অনিযমিতভাবে এইচটি/এসটি শ্রেণির গ্রাহকের সংযোগ প্রদান | G31: এসএফআই | H31: আর্থিক বিধি অনুসরণ না করা | I31: ময়মনসিংহ
A32: 30 | B32: বিক্রয় ও বিতরণ বিভাগ, ঘাটাইল, বিউবো, টাঙ্গাইল | C32: ২০২২-২০২৩ | D32: 70 | E32: কোটেশন দাখিরকারী দরদাতা যোগ্যতার প্রমাণস্বরুপ দলিলাদি দাখিল না করা সত্তেও অনিয়মিতবাবে কোটেশন মূল্যায়নপূর্বক চুক্তি সম্পাদন | F32: 497820 | G32: নন-এসএফআই | H32: আর্থিক বিধি অনুসরণ না করা | I32: ময়মনসিংহ
A33: 31 | B33: বিক্রয় ও বিতরণ বিভাগ, বিউবো, নেত্রকোনা | C33: ১৯৯১-১৯৯৪ | D33: 3 | E33: বৈদ্যুতিক মালামাল চুরি জড়িত টাকা ২,৬৫,৩০৪/- টাকা । | F33: 265304 | G33: এসএফআই | H33: চুরি | I33: ময়মনসিংহ
A34: 32 | B34: বিক্রয় ও বিতরণ বিভাগ, বিউবো, নেত্রকোনা | C34: ২০০৭-২০০৯ | D34: 8 | E34: সংযোগ বিচ্ছিন্নকৃত গ্রাহকের নিকট বকেয়া অনাদায়ী জড়িত টাকা ১৯,৮২,৭৪/- | F34: 1982704 | G34: এসএফআই | H34: বিদ্যুৎ বিল বকেয়া | I34: ময়মনসিংহ
A35: 33 | B35: বিক্রয় ও বিতরণ বিভাগ, বিউবো, নেত্রকোনা | C35: ২০১৩-২০১৫ | D35: 2 | E35: আর্থিক ক্ষমতা বর্হিভূত যানবাহন মেরামত জড়িত টাকা ৯৪১৭২/- | F35: 94172 | G35: এসএফআই | H35: আর্থিক বিধি অনুসরণ না করা | I35: ময়মনসিংহ
A36: 34 | B36: বিক্রয় ও বিতরণ বিভাগ, বিউবো, নেত্রকোনা | C36: ২০১৩-২০১৫ | D36: 6 | E36: বিভিন্ন শ্রেনীর গ্রাহকের নিকট হতে দীর্ঘদিনের বকেয়া বিদ্যুৎ বিলের অর্থ আদায় করা হয়নি । যা জরুরী ভিত্তিতে ৪৭,৩৪,৭২১/- টাকা আদায়যোগ্য । | F36: 4734721 | G36: এসএফআই | H36: বিদ্যুৎ বিল বকেয়া | I36: ময়মনসিংহ
A37: 35 | B37: বিক্রয় ও বিতরণ বিভাগ, বিউবো, ফুলপুর, ময়মনসিংহ | C37: ১৯৯৬-১৯৯৯ | D37: 1 | E37: ১৯৯৬-১৯৯৯ অর্থ বছরে সমূহে রাজস্ব বকেয়া বাবদ ৮১,১২,০৩৪/- টাকা অনাদায়ী । | F37: 8112034 | G37: এসএফআই | H37: বিদ্যুৎ বিল বকেয়া | I37: ময়মনসিংহ
A38: 36 | B38: বিক্রয় ও বিতরণ বিভাগ, বিউবো, ফুলপুর, ময়মনসিংহ | C38: ১৯৯৬-১৯৯৯ | D38: 2 | E38: সিস্টেম লস জড়িত টাকা ৭০,৭৭,০৮৪/- টাকা । | F38: 7077084 | G38: এসএফআই | H38: সিস্টেম লস | I38: ময়মনসিংহ
A39: 37 | B39: বিক্রয় ও বিতরণ বিভাগ, বিউবো, সখিপুর, টাঙ্গাইল | C39: ২০১৭-২০১৮ | D39: 63 | E39: কর্মচারীদের অতিরিক্ত অধিকাল ভাতা প্রদান। জড়িত টাকা ২৫,৬৬,১৯১/- | F39: 2566191 | G39: এসএফআই | H39: অধিকাল ভাতা | I39: ময়মনসিংহ
A40: 38 | B40: বিক্রয় ও বিতরণ বিভাগ, ভৈরব, কিশোরগঞ্জ | C40: ২০২২-২০২৩ | D40: 40.3 | E40: বিভিন্ন শ্রেণীর গ্রাহকের নিকট হতে বকেয়া বিদ্যুৎ বিল আদায় না করায় প্রতিষ্ঠানের আর্থিক ক্ষতি | F40: 3553088 | G40: এসএফআই | H40: বিদ্যুৎ বিল বকেয়া | I40: ময়মনসিংহ
A41: 39 | B41: বিক্রয় ও বিতরণ বিভাগ, ভৈরব, কিশোরগঞ্জ | C41: ২০২২-২০২৩ | D41: 58 | E41: কার্যসমাপ্তির তারিখ নির্দিষ্ট না কওে কার্যাদেশ প্রদান কওে অনিয়মিত ব্যয় | F41: 9062231 | G41: নন-এসএফআই | H41: টেন্ডার ও ক্রয় | I41: ময়মনসিংহ
...

Sheet Total Summary
A1: বাংলাদেশ বিদ্যুৎ উন্নয়ন বোর্ড অনিষ্পন্ন আপত্তি সমুহের হাল নাগাদ অবস্থান ময়মনসিংহ জোন ( এসএফআই এবং এসএফআই ) 18/06/2026খ্রি.
A2: ক্রমিক নং | B2: দপ্তরের নাম | C2: SFI | D2: NON SFI | E2: মোট | F2: ত্রিপক্ষিয় সভায় আলোচনা | G2: ত্রিপক্ষিয় সভায় সুপারিশ | H2: ব্রডশীট জবাব প্রেরণ | I2: নিষ্পত্তির জন্য সুপারিশ
A3: 1 | B3: =Summary_Mymenshing!B3 -> বিক্রয় ও বিতরণ বিভাগ, বিউবো, নেত্রকোনা | C3: =Summary_Mymenshing!C3 -> 4 | D3: =Summary_Mymenshing!D3 -> 0 | E3: =Summary_Mymenshing!E3 -> 4 | F3: =Summary_Mymenshing!F3 -> 3 | G3: =Summary_Mymenshing!G3 -> 3 | H3: =Summary_Mymenshing!H3 -> 3 | I3: =Summary_Mymenshing!I3 -> 6
A4: 2 | B4: =Summary_Mymenshing!B4 -> আঞ্চলিক পূর্ত নির্মাণ বিভাগ, বিউবো, ময়মনসিংহ | C4: =Summary_Mymenshing!C4 -> 9 | D4: =Summary_Mymenshing!D4 -> 1 | E4: =Summary_Mymenshing!E4 -> 10 | F4: =Summary_Mymenshing!F4 -> 2 | G4: =Summary_Mymenshing!G4 -> 2 | H4: =Summary_Mymenshing!H4 -> 8 | I4: =Summary_Mymenshing!I4 -> 10
A5: 3 | B5: =Summary_Mymenshing!B5 -> নির্বাহী প্রকৌশলী, বিক্রয় ও বিতরণ বিভাগ-২ (দক্ষিণ), বিউবো, ময়মনসিংহ | C5: =Summary_Mymenshing!C5 -> 10 | D5: =Summary_Mymenshing!D5 -> 2 | E5: =Summary_Mymenshing!E5 -> 12 | F5: =Summary_Mymenshing!F5 -> 5 | G5: =Summary_Mymenshing!G5 -> 5 | H5: =Summary_Mymenshing!H5 -> 7 | I5: =Summary_Mymenshing!I5 -> 12
A6: 4 | B6: =Summary_Mymenshing!B6 -> বিক্রয় ও বিতরণ বিভাগ-৩, বিউবো, ময়মনসিংহ | C6: =Summary_Mymenshing!C6 -> 10 | D6: =Summary_Mymenshing!D6 -> 0 | E6: =Summary_Mymenshing!E6 -> 10 | F6: =Summary_Mymenshing!F6 -> 0 | G6: =Summary_Mymenshing!G6 -> 0 | H6: =Summary_Mymenshing!H6 -> 6 | I6: =Summary_Mymenshing!I6 -> 6
A7: 5 | B7: =Summary_Mymenshing!B7 -> বিক্রয় ও বিতরণ বিভাগ-২, বিউবো, টাঙ্গাইল | C7: =Summary_Mymenshing!C7 -> 6 | D7: =Summary_Mymenshing!D7 -> 1 | E7: =Summary_Mymenshing!E7 -> 7 | F7: =Summary_Mymenshing!F7 -> 1 | G7: =Summary_Mymenshing!G7 -> 1 | H7: =Summary_Mymenshing!H7 -> 5 | I7: =Summary_Mymenshing!I7 -> 6
A8: 6 | B8: =Summary_Mymenshing!B8 -> নির্বাহী প্রকৌশলী, বিক্রয় ও বিতরণ বিভাগ, কিশোরগঞ্জ | C8: =Summary_Mymenshing!C8 -> 1 | D8: =Summary_Mymenshing!D8 -> 1 | E8: =Summary_Mymenshing!E8 -> 2 | F8: =Summary_Mymenshing!F8 -> 1 | G8: =Summary_Mymenshing!G8 -> 1 | H8: =Summary_Mymenshing!H8 -> 0 | I8: =Summary_Mymenshing!I8 -> 1
A9: 7 | B9: =Summary_Mymenshing!B9 -> প্রকল্প পরিচালক, বিদ্যুৎ ব্যবস্থা উন্নয়ন প্রকল্প, ময়মনসিংহ | C9: =Summary_Mymenshing!C9 -> 19 | D9: =Summary_Mymenshing!D9 -> 3 | E9: =Summary_Mymenshing!E9 -> 22 | F9: =Summary_Mymenshing!F9 -> 7 | G9: =Summary_Mymenshing!G9 -> 7 | H9: =Summary_Mymenshing!H9 -> 12 | I9: =Summary_Mymenshing!I9 -> 19
A10: 8 | B10: =Summary_Mymenshing!B10 -> নির্বাহী প্রকৌশলী, বিক্রয় ও বিতরন বিভাগ-১ (উত্তর), বিউবো, ময়মনসিংহ। | C10: =Summary_Mymenshing!C10 -> 5 | D10: =Summary_Mymenshing!D10 -> 2 | E10: =Summary_Mymenshing!E10 -> 7 | F10: =Summary_Mymenshing!F10 -> 5 | G10: =Summary_Mymenshing!G10 -> 2 | H10: =Summary_Mymenshing!H10 -> 5 | I10: =Summary_Mymenshing!I10 -> 7
A11: 9 | B11: =Summary_Mymenshing!B11 -> বিক্রয় ও বিতরণ বিভাগ -ত্রিশাল, বিউবো, ময়মনসিংহ | C11: =Summary_Mymenshing!C11 -> 1 | D11: =Summary_Mymenshing!D11 -> 0 | E11: =Summary_Mymenshing!E11 -> 1 | F11: =Summary_Mymenshing!F11 -> 1 | G11: =Summary_Mymenshing!G11 -> 1 | H11: =Summary_Mymenshing!H11 -> 0 | I11: =Summary_Mymenshing!I11 -> 1
A12: 10 | B12: =Summary_Mymenshing!B12 -> বিক্রয় ও বিতরণ বিভাগ -ভালুকা, বিউবো, ময়মনসিংহ | C12: =Summary_Mymenshing!C12 -> 0 | D12: =Summary_Mymenshing!D12 -> 1 | E12: =Summary_Mymenshing!E12 -> 1 | F12: =Summary_Mymenshing!F12 -> 1 | G12: =Summary_Mymenshing!G12 -> 1 | H12: =Summary_Mymenshing!H12 -> 0 | I12: =Summary_Mymenshing!I12 -> 1
A13: 11 | B13: =Summary_Mymenshing!B13 -> বিক্রয় ও বিতরণ বিভাগ, বিউবো, সখিপুর, টাঙ্গাইল | C13: =Summary_Mymenshing!C13 -> 1 | D13: =Summary_Mymenshing!D13 -> 0 | E13: =Summary_Mymenshing!E13 -> 1 | F13: =Summary_Mymenshing!F13 -> 1 | G13: =Summary_Mymenshing!G13 -> 1 | H13: =Summary_Mymenshing!H13 -> 1 | I13: =Summary_Mymenshing!I13 -> 2
A14: 12 | B14: =Summary_Mymenshing!B14 -> নির্বাহী প্রকৌশলী, বিক্রয় ও বিতরন বিভাগ-১, বিউবো, টাংগাইল। | C14: =Summary_Mymenshing!C14 -> 15 | D14: =Summary_Mymenshing!D14 -> 6 | E14: =Summary_Mymenshing!E14 -> 21 | F14: =Summary_Mymenshing!F14 -> 12 | G14: =Summary_Mymenshing!G14 -> 9 | H14: =Summary_Mymenshing!H14 -> 7 | I14: =Summary_Mymenshing!I14 -> 16
... A28: 26 | B28: =Summary_Mymenshing!B28 -> নির্বাহী প্রকৌশলী, বিক্রয় ও বিতরণ বিভাগ, ভৈরব, কিশোরগঞ্জ | C28: =Summary_Mymenshing!C28 -> 1 | D28: =Summary_Mymenshing!D28 -> 3 | E28: =Summary_Mymenshing!E28 -> 4 | F28: =Summary_Mymenshing!F28 -> 3 | G28: =Summary_Mymenshing!G28 -> 3 | H28: =Summary_Mymenshing!H28 -> 0 | I28: =Summary_Mymenshing!I28 -> 3
A29: 27 | B29: =Summary_Chittagong!B9 -> প্রধান প্রকৌশলী দক্ষিণাঞ্চল চট্টগ্রাম | C29: =Summary_Chittagong!C9 -> 0 | D29: =Summary_Chittagong!D9 -> 1 | E29: =Summary_Chittagong!E9 -> 1 | F29: =Summary_Chittagong!F9 -> 0 | G29: =Summary_Chittagong!G9 -> 0 | H29: =Summary_Chittagong!H9 -> 0 | I29: =Summary_Chittagong!I9 -> 0
A30: 28 | B30: =Summary_Chittagong!B10 -> বিক্রয় ও বিতৰণ বিভাগ, কালুৰঘাট, চট্টগ্রাম | C30: =Summary_Chittagong!C10 -> 2 | D30: =Summary_Chittagong!D10 -> 17 | E30: =Summary_Chittagong!E10 -> 19 | F30: =Summary_Chittagong!F10 -> 2 | G30: =Summary_Chittagong!G10 -> 2 | H30: =Summary_Chittagong!H10 -> 0 | I30: =Summary_Chittagong!I10 -> 2
A31: 29 | B31: =Summary_Chittagong!B11 -> বিক্রয় ও বিতৰণ বিভাগ, পাথৰঘাটা, চট্টগ্রাম | C31: =Summary_Chittagong!C11 -> 0 | D31: =Summary_Chittagong!D11 -> 9 | E31: =Summary_Chittagong!E11 -> 9 | F31: =Summary_Chittagong!F11 -> 0 | G31: =Summary_Chittagong!G11 -> 0 | H31: =Summary_Chittagong!H11 -> 4 | I31: =Summary_Chittagong!I11 -> 4
A32: 30 | B32: =Summary_Chittagong!B12 -> বিক্রয় ও বিতৰণ বিভাগ, স্টেডিয়াম, চট্টগ্রাম | C32: =Summary_Chittagong!C12 -> 1 | D32: =Summary_Chittagong!D12 -> 10 | E32: =Summary_Chittagong!E12 -> 11 | F32: =Summary_Chittagong!F12 -> 3 | G32: =Summary_Chittagong!G12 -> 3 | H32: =Summary_Chittagong!H12 -> 4 | I32: =Summary_Chittagong!I12 -> 7
A33: 31 | B33: =Summary_Chittagong!B13 -> বিক্রয় ও বিতৰণ বিভাগ, ষোলশহৰ, চট্টগ্রাম | C33: =Summary_Chittagong!C13 -> 2 | D33: =Summary_Chittagong!D13 -> 9 | E33: =Summary_Chittagong!E13 -> 11 | F33: =Summary_Chittagong!F13 -> 0 | G33: =Summary_Chittagong!G13 -> 0 | H33: =Summary_Chittagong!H13 -> 0 | I33: =Summary_Chittagong!I13 -> 0
A34: 32 | B34: =Summary_Chittagong!B14 -> বিক্রয় ও বিতরণ বিভাগ, বাকলিয়া, চট্টগ্রাম | C34: =Summary_Chittagong!C14 -> 0 | D34: =Summary_Chittagong!D14 -> 7 | E34: =Summary_Chittagong!E14 -> 7 | F34: =Summary_Chittagong!F14 -> 4 | G34: =Summary_Chittagong!G14 -> 2 | H34: =Summary_Chittagong!H14 -> 0 | I34: =Summary_Chittagong!I14 -> 2
A35: 33 | B35: =Summary_Chittagong!B15 -> পরিচালন ও সংরক্ষণ সার্কেল চট্টঃমেট্রোঃ পশ্চিম | C35: =Summary_Chittagong!C15 -> 0 | D35: =Summary_Chittagong!D15 -> 1 | E35: =Summary_Chittagong!E15 -> 1 | F35: =Summary_Chittagong!F15 -> 0 | G35: =Summary_Chittagong!G15 -> 0 | H35: =Summary_Chittagong!H15 -> 0 | I35: =Summary_Chittagong!I15 -> 0
A36: 34 | B36: =Summary_Chittagong!B16 -> বিক্রয় ও বিতরণ বিভাগ, আগ্রাবাদ, চট্টগ্রাম | C36: =Summary_Chittagong!C16 -> 1 | D36: =Summary_Chittagong!D16 -> 8 | E36: =Summary_Chittagong!E16 -> 9 | F36: =Summary_Chittagong!F16 -> 0 | G36: =Summary_Chittagong!G16 -> 0 | H36: =Summary_Chittagong!H16 -> 0 | I36: =Summary_Chittagong!I16 -> 0
A37: 35 | B37: =Summary_Chittagong!B17 -> বিক্রয় ও বিতরণ বিভাগ, খুলশী, চট্টগ্রাম | C37: =Summary_Chittagong!C17 -> 1 | D37: =Summary_Chittagong!D17 -> 25 | E37: =Summary_Chittagong!E17 -> 26 | F37: =Summary_Chittagong!F17 -> 5 | G37: =Summary_Chittagong!G17 -> 1 | H37: =Summary_Chittagong!H17 -> 12 | I37: =Summary_Chittagong!I17 -> 13
A38: 36 | B38: =Summary_Chittagong!B18 -> বিক্রয় ও বিতরণ বিভাগ, পাহাড়তলী, চট্টগ্রাম | C38: =Summary_Chittagong!C18 -> 2 | D38: =Summary_Chittagong!D18 -> 4 | E38: =Summary_Chittagong!E18 -> 6 | F38: =Summary_Chittagong!F18 -> 0 | G38: =Summary_Chittagong!G18 -> 0 | H38: =Summary_Chittagong!H18 -> 3 | I38: =Summary_Chittagong!I18 -> 3
A39: 37 | B39: =Summary_Chittagong!B19 -> বিক্রয় ও বিতরণ বিভাগ, হালিশহর, চট্টগ্রাম | C39: =Summary_Chittagong!C19 -> 3 | D39: =Summary_Chittagong!D19 -> 21 | E39: =Summary_Chittagong!E19 -> 24 | F39: =Summary_Chittagong!F19 -> 0 | G39: =Summary_Chittagong!G19 -> 0 | H39: =Summary_Chittagong!H19 -> 4 | I39: =Summary_Chittagong!I19 -> 4
A40: 38 | B40: =Summary_Chittagong!B20 -> বিক্রয় ও বিতরণ বিভাগ, নিউমুরিং, চট্টগ্রাম | C40: =Summary_Chittagong!C20 -> 1 | D40: =Summary_Chittagong!D20 -> 6 | E40: =Summary_Chittagong!E20 -> 7 | F40: =Summary_Chittagong!F20 -> 0 | G40: =Summary_Chittagong!G20 -> 0 | H40: =Summary_Chittagong!H20 -> 4 | I40: =Summary_Chittagong!I20 -> 4
... A66: 64 | B66: =Summary_Chittagong!B46 -> শিকলবাহা ২২৫ মেঃ ওঃবিদ্যুৎ কেন্দ্র বিউবো, চট্টগ্রাম | C66: =Summary_Chittagong!C46 -> 1 | D66: =Summary_Chittagong!D46 -> 5 | E66: =Summary_Chittagong!E46 -> 6 | F66: =Summary_Chittagong!F46 -> 0 | G66: =Summary_Chittagong!G46 -> 0 | H66: =Summary_Chittagong!H46 -> 6 | I66: =Summary_Chittagong!I46 -> 6
A67: 65 | B67: =Summary_Comilla!B6 -> বিক্রয় ও বিতরন বিভাগ- 1, Kzwgল্লা | C67: =Summary_Comilla!C6 -> 1 | D67: =Summary_Comilla!D6 -> 17 | E67: =Summary_Comilla!E6 -> 18 | F67: =Summary_Comilla!F6 -> 4 | G67: =Summary_Comilla!G6 -> 3 | H67: =Summary_Comilla!H6 -> 3 | I67: =Summary_Comilla!I6 -> 6
A68: 66 | B68: =Summary_Comilla!B7 -> বিক্রয় ও বিতরন বিভাগ- 2, Kzwgল্লা | C68: =Summary_Comilla!C7 -> 1 | D68: =Summary_Comilla!D7 -> 24 | E68: =Summary_Comilla!E7 -> 25 | F68: =Summary_Comilla!F7 -> 0 | G68: =Summary_Comilla!G7 -> 0 | H68: =Summary_Comilla!H7 -> 3 | I68: =Summary_Comilla!I7 -> 3
A69: 67 | B69: =Summary_Comilla!B8 -> বিক্রয় ও বিতরন বিভাগ- 3, Kzwgল্লা | C69: =Summary_Comilla!C8 -> 0 | D69: =Summary_Comilla!D8 -> 12 | E69: =Summary_Comilla!E8 -> 12 | F69: =Summary_Comilla!F8 -> 0 | G69: =Summary_Comilla!G8 -> 0 | H69: =Summary_Comilla!H8 -> 2 | I69: =Summary_Comilla!I8 -> 2
A70: 68 | B70: =Summary_Comilla!B9 -> চৌদ্দগ্রাম বিদ্যুৎ সরবরাহ | C70: =Summary_Comilla!C9 -> 0 | D70: =Summary_Comilla!D9 -> 1 | E70: =Summary_Comilla!E9 -> 1 | F70: =Summary_Comilla!F9 -> 0 | G70: =Summary_Comilla!G9 -> 0 | H70: =Summary_Comilla!H9 -> 0 | I70: =Summary_Comilla!I9 -> 0
A71: 69 | B71: =Summary_Comilla!B10 -> Pvu`cyi 150 †gtIt we`y¨r †K›`ª | C71: =Summary_Comilla!C10 -> 0 | D71: =Summary_Comilla!D10 -> 2 | E71: =Summary_Comilla!E10 -> 2 | F71: =Summary_Comilla!F10 -> 0 | G71: =Summary_Comilla!G10 -> 0 | H71: =Summary_Comilla!H10 -> 0 | I71: =Summary_Comilla!I10 -> 0
A72: 70 | B72: =Summary_Comilla!B11 -> বিক্রয় ও বিতরন বিভাগ- চাঁদপুর | C72: =Summary_Comilla!C11 -> 1 | D72: =Summary_Comilla!D11 -> 14 | E72: =Summary_Comilla!E11 -> 15 | F72: =Summary_Comilla!F11 -> 3 | G72: =Summary_Comilla!G11 -> 1 | H72: =Summary_Comilla!H11 -> 0 | I72: =Summary_Comilla!I11 -> 1
A73: 71 | B73: =Summary_Comilla!B12 -> বিক্রয় ও বিতরন বিভাগ- নোয়াখালী | C73: =Summary_Comilla!C12 -> 2 | D73: =Summary_Comilla!D12 -> 16 | E73: =Summary_Comilla!E12 -> 18 | F73: =Summary_Comilla!F12 -> 0 | G73: =Summary_Comilla!G12 -> 0 | H73: =Summary_Comilla!H12 -> 0 | I73: =Summary_Comilla!I12 -> 0
A74: 72 | B74: =Summary_Comilla!B13 -> jÿxcyi we`y¨r mieivn | C74: =Summary_Comilla!C13 -> 2 | D74: =Summary_Comilla!D13 -> 8 | E74: =Summary_Comilla!E13 -> 10 | F74: =Summary_Comilla!F13 -> 0 | G74: =Summary_Comilla!G13 -> 0 | H74: =Summary_Comilla!H13 -> 0 | I74: =Summary_Comilla!I13 -> 0
A75: 73 | B75: =Summary_Comilla!B14 -> †PŠgynbx we`y¨r mieivn | C75: =Summary_Comilla!C14 -> 0 | D75: =Summary_Comilla!D14 -> 7 | E75: =Summary_Comilla!E14 -> 7 | F75: =Summary_Comilla!F14 -> 0 | G75: =Summary_Comilla!G14 -> 0 | H75: =Summary_Comilla!H14 -> 0 | I75: =Summary_Comilla!I14 -> 0
A76: 74 | B76: =Summary_Comilla!B15 -> বিক্রয় ও বিতরন বিভাগ- ফেনী | C76: =Summary_Comilla!C15 -> 2 | D76: =Summary_Comilla!D15 -> 24 | E76: =Summary_Comilla!E15 -> 26 | F76: =Summary_Comilla!F15 -> 3 | G76: =Summary_Comilla!G15 -> 1 | H76: =Summary_Comilla!H15 -> 3 | I76: =Summary_Comilla!I15 -> 4
A77: 75 | B77: =Summary_Comilla!B16 -> বিক্রয় ও বিতরন বিভাগ- 1, বি,বাড়িয়া | C77: =Summary_Comilla!C16 -> 3 | D77: =Summary_Comilla!D16 -> 11 | E77: =Summary_Comilla!E16 -> 14 | F77: =Summary_Comilla!F16 -> 0 | G77: =Summary_Comilla!G16 -> 0 | H77: =Summary_Comilla!H16 -> 0 | I77: =Summary_Comilla!I16 -> 0
A78: 76 | B78: =Summary_Comilla!B17 -> বিক্রয় ও বিতরন বিভাগ- 2, বি,বাড়িয়া | C78: =Summary_Comilla!C17 -> 0 | D78: =Summary_Comilla!D17 -> 3 | E78: =Summary_Comilla!E17 -> 3 | F78: =Summary_Comilla!F17 -> 2 | G78: =Summary_Comilla!G17 -> 2 | H78: =Summary_Comilla!H17 -> 0 | I78: =Summary_Comilla!I17 -> 2
...

Sheet Summary_Mymenshing
A1: বাংলাদেশ বিদ্যুৎ উন্নয়ন বোর্ড অনিষ্পন্ন আপত্তি সমুহের হাল নাগাদ অবস্থান ময়মনসিংহ জোন ( এসএফআই এবং এসএফআই ) 18/06/2026খ্রি.
A2: ক্রমিক নং | B2: দপ্তরের নাম | C2: SFI | D2: NON SFI | E2: মোট | F2: ত্রিপক্ষিয় সভায় আলোচনা | G2: ত্রিপক্ষিয় সভায় সুপারিশ | H2: ব্রডশীট জবাব প্রেরণ | I2: নিষ্পত্তির জন্য সুপারিশ
A3: 1 | B3: বিক্রয় ও বিতরণ বিভাগ, বিউবো, নেত্রকোনা | C3: 4 | D3: 0 | E3: 4 | F3: 3 | G3: 3 | H3: 3 | I3: 6
A4: 2 | B4: আঞ্চলিক পূর্ত নির্মাণ বিভাগ, বিউবো, ময়মনসিংহ | C4: 9 | D4: 1 | E4: 10 | F4: 2 | G4: 2 | H4: 8 | I4: 10
A5: 3 | B5: নির্বাহী প্রকৌশলী, বিক্রয় ও বিতরণ বিভাগ-২ (দক্ষিণ), বিউবো, ময়মনসিংহ | C5: =4+1+1+1+1+1+1 -> 10 | D5: =2 -> 2 | E5: 12 | F5: 5 | G5: 5 | H5: 7 | I5: 12
A6: 4 | B6: বিক্রয় ও বিতরণ বিভাগ-৩, বিউবো, ময়মনসিংহ | C6: =1+1+1+1+1+1+4 -> 10 | D6: 0 | E6: 10 | H6: 6 | I6: 6
A7: 5 | B7: বিক্রয় ও বিতরণ বিভাগ-২, বিউবো, টাঙ্গাইল | C7: 6 | D7: 1 | E7: 7 | F7: 1 | G7: 1 | H7: 5 | I7: 6
A8: 6 | B8: নির্বাহী প্রকৌশলী, বিক্রয় ও বিতরণ বিভাগ, কিশোরগঞ্জ | C8: 1 | D8: 1 | E8: 2 | F8: 1 | G8: 1 | I8: 1
A9: 7 | B9: প্রকল্প পরিচালক, বিদ্যুৎ ব্যবস্থা উন্নয়ন প্রকল্প, ময়মনসিংহ | C9: 19 | D9: 3 | E9: 22 | F9: 7 | G9: 7 | H9: 12 | I9: 19
A10: 8 | B10: নির্বাহী প্রকৌশলী, বিক্রয় ও বিতরন বিভাগ-১ (উত্তর), বিউবো, ময়মনসিংহ। | C10: 5 | D10: 2 | E10: 7 | F10: 5 | G10: 2 | H10: 5 | I10: 7
A11: 9 | B11: বিক্রয় ও বিতরণ বিভাগ -ত্রিশাল, বিউবো, ময়মনসিংহ | C11: 1 | D11: 0 | E11: 1 | F11: 1 | G11: 1 | I11: 1
A12: 10 | B12: বিক্রয় ও বিতরণ বিভাগ -ভালুকা, বিউবো, ময়মনসিংহ | C12: 0 | D12: 1 | E12: 1 | F12: 1 | G12: 1 | I12: 1
A13: 11 | B13: বিক্রয় ও বিতরণ বিভাগ, বিউবো, সখিপুর, টাঙ্গাইল | C13: 1 | D13: 0 | E13: 1 | F13: 1 | G13: 1 | H13: 1 | I13: 2
A14: 12 | B14: নির্বাহী প্রকৌশলী, বিক্রয় ও বিতরন বিভাগ-১, বিউবো, টাংগাইল। | C14: 15 | D14: 6 | E14: 21 | F14: 12 | G14: 9 | H14: 7 | I14: 16
A15: 13 | B15: আবাসিক প্রকৌশলী, গৌরীপুর বিদ্যুৎ সরবরাহ, বিউবেো, ময়মনসিংহ | C15: 1 | D15: 0 | E15: 1 | H15: 1 | I15: 1
A16: 14 | B16: আবাসিক প্রকৌশলী, ঈশ^রগঞ্জ বিদ্যুৎ সরবরাহ, বিউবো, ময়মনসিংহ | C16: 1 | D16: 0 | E16: 1
A17: 15 | B17: বিতরণ বিভাগ, বিউবো, জামালপুর | C17: 4 | D17: 1 | E17: 5 | F17: 1 | G17: 1 | I17: 1
A18: 16 | B18: বিক্রয় ও বিতরণ বিভাগ, সরিষাবাড়ী, বিউবো, জামালপুর | C18: 3 | D18: 2 | E18: 5 | F18: 5 | G18: 4 | H18: 1 | I18: 5
A19: 17 | B19: নির্বাহী প্রকৌশলী, বিতরণ বিভাগ, বিউবো, শেরপুর। | C19: 3 | D19: 0 | E19: 3 | F19: 2 | G19: 1 | H19: 2 | I19: 3
A20: 18 | B20: বিক্রয় ও বিতরণ বিভাগ, বিউবো, ফুলপুর, ময়মনসিংহ | C20: 2 | D20: 0 | E20: 2 | F20: 1 | G20: 1 | H20: 1 | I20: 2
A21: 19 | B21: বিক্রয় ও বিতরণ বিভাগ, ঘাটাইল, বিউবো, টাঙ্গাইল | D21: 1 | E21: 1 | F21: 1
A22: 20 | B22: শান্তাহার 50মেঃওঃ পিকিংবিদ্যুৎ কেন্দ্র , বগুড়া। | C22: 5 | E22: 5 | H22: 4 | I22: 4
A23: 21 | B23: কাটাখালী 50মেঃওঃ পিকিংবিদ্যুৎ কেন্দ্র , রাজশাহী | C23: 6 | E23: 6 | H23: 5 | I23: 5
A24: 22 | B24: চাপাইনবাবগঞ্জ 100মেঃওঃ পিকিং বিদ্যুৎ কেন্দ্র,আমনুরা,চাপাইনবাবগঞ্জ | C24: 6 | D24: 1 | E24: 7 | H24: 6 | I24: 6
A25: 23 | B25: নির্বাহী প্রকৌশলী, পিসিপোল নির্মান কারখানা, নিলফামারী | C25: 5 | E25: 5 | H25: 4 | I25: 4
A26: 24 | B26: নির্বাহী প্রকৌশলী, বিক্রয় ও বিতরণ বিভাগ, বাজিতপুর, কিশোরগঞ্জ | C26: 2 | E26: 2 | F26: 1 | G26: 1 | I26: 1
A27: 25 | B27: নির্বাহী প্রকৌশলী, বিক্রয় ও বিতরণ বিভাগ, কিশোরগঞ্জ | C27: 1 | D27: 1 | E27: 2 | F27: 1 | G27: 1 | I27: 1
A28: 26 | B28: নির্বাহী প্রকৌশলী, বিক্রয় ও বিতরণ বিভাগ, ভৈরব, কিশোরগঞ্জ | C28: 1 | D28: 3 | E28: 4 | F28: 3 | G28: 3 | I28: 3
A29: মোট | C29: =SUM(C3:C28) -> 121 | D29: =SUM(D3:D28) -> 26 | E29: =SUM(E3:E28) -> 147 | F29: =SUM(F3:F28) -> 54 | G29: =SUM(G3:G28) -> 45 | H29: =SUM(H3:H28) -> 78 | I29: =SUM(I3:I28) -> 123

Sheet Summary_Chittagong
B1: চট্টগ্রাম জোন (এস এফ আই)
A3: র্ | B3: বাংলাদেশ বিদ্যুৎ উন্নয়ন বোর্ড
B4: অরিষ্পন্ন অডিট আপত্তির প্রতিবেদন
B5: চট্টগ্রাম জোন
A6: ক্রমিক নং | B6: দপ্তরের নাম | C6: Non SFI (সাধারণ) | D6: SFI | E6: মোট | F6: ত্রি-পক্ষীয় সভায় আলেচনা (SFI) | G6: ত্রি-পক্ষীয় সভায় সুপারিশ (SFI) | H6: ব্রডশীট জবাব প্রেরণ (SFI) | I6: নিষ্টত্তির জন্য সুপারিশ
D7: (অগ্রিম)
A8: 1 | B8: 2 | C8: 3 | D8: 4 | E8: 5=(3+4) | F8: 6 | G8: 7 | H8: 8 | I8: 9=7+8
A9: 1 | B9: প্রধান প্রকৌশলী দক্ষিণাঞ্চল চট্টগ্রাম | D9: 1 | E9: =C9+D9 -> 1 | I9: =G9+H9 -> 0
A10: 2 | B10: বিক্রয় ও বিতৰণ বিভাগ, কালুৰঘাট, চট্টগ্রাম | C10: 2 | D10: 17 | E10: =C10+D10 -> 19 | F10: 2 | G10: 2 | I10: =G10+H10 -> 2
A11: 3 | B11: বিক্রয় ও বিতৰণ বিভাগ, পাথৰঘাটা, চট্টগ্রাম | D11: 9 | E11: =C11+D11 -> 9 | H11: 4 | I11: =G11+H11 -> 4
A12: 4 | B12: বিক্রয় ও বিতৰণ বিভাগ, স্টেডিয়াম, চট্টগ্রাম | C12: 1 | D12: 10 | E12: =C12+D12 -> 11 | F12: 3 | G12: 3 | H12: 4 | I12: =G12+H12 -> 7
A13: 5 | B13: বিক্রয় ও বিতৰণ বিভাগ, ষোলশহৰ, চট্টগ্রাম | C13: 2 | D13: 9 | E13: =C13+D13 -> 11 | I13: =G13+H13 -> 0
A14: 6 | B14: বিক্রয় ও বিতরণ বিভাগ, বাকলিয়া, চট্টগ্রাম | D14: 7 | E14: =C14+D14 -> 7 | F14: 4 | G14: 2 | I14: =G14+H14 -> 2
A15: 7 | B15: পরিচালন ও সংরক্ষণ সার্কেল চট্টঃমেট্রোঃ পশ্চিম | D15: 1 | E15: =C15+D15 -> 1 | I15: =G15+H15 -> 0
A16: 8 | B16: বিক্রয় ও বিতরণ বিভাগ, আগ্রাবাদ, চট্টগ্রাম | C16: 1 | D16: 8 | E16: =C16+D16 -> 9 | I16: =G16+H16 -> 0
A17: 9 | B17: বিক্রয় ও বিতরণ বিভাগ, খুলশী, চট্টগ্রাম | C17: 1 | D17: 25 | E17: =C17+D17 -> 26 | F17: 5 | G17: 1 | H17: 12 | I17: =G17+H17 -> 13
A18: 10 | B18: বিক্রয় ও বিতরণ বিভাগ, পাহাড়তলী, চট্টগ্রাম | C18: 2 | D18: 4 | E18: =C18+D18 -> 6 | H18: 3 | I18: =G18+H18 -> 3
A19: 11 | B19: বিক্রয় ও বিতরণ বিভাগ, হালিশহর, চট্টগ্রাম | C19: 3 | D19: 21 | E19: =C19+D19 -> 24 | H19: 4 | I19: =G19+H19 -> 4
A20: 12 | B20: বিক্রয় ও বিতরণ বিভাগ, নিউমুরিং, চট্টগ্রাম | C20: 1 | D20: 6 | E20: =C20+D20 -> 7 | H20: 4 | I20: =G20+H20 -> 4
A21: 13 | B21: বিক্রয় ও বিতরণ বিভাগ, রামপুর, চট্টগ্রাম | D21: 4 | E21: =C21+D21 -> 4 | F21: 3 | G21: 2 | I21: =G21+H21 -> 2
A22: 14 | B22: বিক্রয় ও বিতরণ বিভাগ, ফৌজদারহাট, চট্টগ্রাম | D22: 9 | E22: =C22+D22 -> 9 | F22: 2 | G22: 2 | I22: =G22+H22 -> 2
A23: 16 | B23: বিক্রয় ও বিতরণ বিভাগ, হাটহাজারী, চট্টগ্রাম | C23: 1 | D23: 10 | E23: =C23+D23 -> 11 | F23: 5 | G23: 3 | I23: =G23+H23 -> 3
A24: 17 | B24: বিক্রয় ও বিতরণ বিভাগ, মোহরা, চট্টগ্রাম | D24: 1 | E24: =C24+D24 -> 1 | H24: 1 | I24: =G24+H24 -> 1
A25: 18 | B25: বিক্রয় ও বিতরণ বিভাগ, পটিয়া, চট্টগ্রাম | C25: 1 | D25: 10 | E25: =C25+D25 -> 11 | I25: =G25+H25 -> 0
A26: 19 | B26: দোহাজারী বিদ্যুৎ সরবরাহ, চট্টগ্রাম | D26: 1 | E26: =C26+D26 -> 1 | I26: =G26+H26 -> 0
A27: 20 | B27: বিক্রয় ও বিতরণ বিভাগ, কক্সবাজার | C27: 5 | D27: 16 | E27: =C27+D27 -> 21 | F27: 4 | G27: 2 | I27: =G27+H27 -> 2
A28: 21 | B28: চকোরিয়া বিদ্যুৎ সরবরাহ | D28: 1 | E28: =C28+D28 -> 1 | I28: =G28+H28 -> 0
A29: 22 | B29: রামু বিদ্যুৎ সরবরাহ | D29: 2 | E29: =C29+D29 -> 2 | I29: =G29+H29 -> 0
A30: 23 | B30: লামা বিদ্যুৎ সরবরাহ | D30: 1 | E30: =C30+D30 -> 1 | I30: =G30+H30 -> 0
A31: 24 | B31: কুতুবদিয়া বিদ্যুৎ সরবরাহ | D31: 2 | E31: =C31+D31 -> 2 | I31: =G31+H31 -> 0
A32: 25 | B32: বিক্রয় ও বিতরণ বিভাগ, রাঙ্গামাটি | C32: 1 | D32: 14 | E32: =C32+D32 -> 15 | F32: 4 | G32: 3 | I32: =G32+H32 -> 3
A33: 26 | B33: বিক্রয় ও বিতরণ বিভাগ, খাগড়াছড়ি | C33: 1 | D33: 4 | E33: =C33+D33 -> 5 | I33: =G33+H33 -> 0
A34: 27 | B34: রামগড় বিদ্যুৎ সরবরাহ | D34: 1 | E34: =C34+D34 -> 1 | I34: =G34+H34 -> 0
A35: 28 | B35: বিক্রয় ও বিতরণ বিভাগ, বান্দরবান | C35: 2 | D35: 5 | E35: =C35+D35 -> 7 | I35: =G35+H35 -> 0
A36: 29 | B36: স্ক্যডা পরিচালন বিভাগ | D36: 1 | E36: =C36+D36 -> 1 | I36: =G36+H36 -> 0
A37: 30 | B37: কেন্দ্রীয় ভান্ডার, চট্টগ্রাম | D37: 3 | E37: =C37+D37 -> 3 | I37: =G37+H37 -> 0
A38: 31 | B38: আঞ্চলিক পূর্ত নির্মাণ বিভাগ | C38: 5 | D38: 13 | E38: =C38+D38 -> 18 | F38: 3 | G38: 1 | H38: 4 | I38: =G38+H38 -> 5
A39: 32 | B39: পিসি পোল নির্মাণ প্ল্যান্ট | C39: 2 | D39: 17 | E39: =C39+D39 -> 19 | F39: 3 | G39: 1 | H39: 5 | I39: =G39+H39 -> 6
A40: 33 | B40: প্রকল্প পরিচালক, বিদ্যুৎ বিতরণ ব্যবস্থা উন্নয়ন প্রকল্প, চট্টগ্রাম, জোন। | C40: 2 | D40: 4 | E40: =C40+D40 -> 6 | I40: =G40+H40 -> 0
A41: 34 | B41: প্রকল্প পরিচালক, বিদ্যুৎ বিতরণ ব্যবস্থা উন্নয়ন প্রকল্প (২য় পর্যায়), চট্টগ্রাম, জোন। | D41: 26 | E41: =C41+D41 -> 26 | F41: 7 | G41: 4 | H41: 8 | I41: =G41+H41 -> 12
...

Sheet Summary_Comilla
A1: বাংলাদেশ বিদ্যুৎ উন্নয়ন বোর্ড
A2: অনিষ্পন্ন অডিট আপত্তির প্রতিবেদন্ত
A3: কুমিল্লা জোন (17-06-2026 পর্যন্ত)
A4: ক্রমিক নং | B4: দপ্তরের নাম | C4: Non SFI (সাধারণ) | D4: SFI (অগ্রিম) | E4: মোট আপত্তির সংখ্যা | F4: ত্রি পক্ষীয় সভায় আলোচনা (SFI) | G4: ত্রি পক্ষীয় সভায় সুপারিশ (SFI) | H4: ব্রডশীট জবাব প্রেরণ SFI | I4: নিষ্পত্তির জন্য সুপারিশ
A5: 1 | B5: 2 | C5: 3 | D5: 4 | E5: 5 | F5: 6 | G5: 7 | H5: 8 | I5: 9=(7+8)
A6: 1 | B6: বিক্রয় ও বিতরন বিভাগ- 1, Kzwgল্লা | C6: 1 | D6: 17 | E6: =C6+D6 -> 18 | F6: 4 | G6: 3 | H6: 3 | I6: =G6+H6 -> 6
A7: 2 | B7: বিক্রয় ও বিতরন বিভাগ- 2, Kzwgল্লা | C7: 1 | D7: 24 | E7: =C7+D7 -> 25 | H7: 3 | I7: =G7+H7 -> 3
A8: 3 | B8: বিক্রয় ও বিতরন বিভাগ- 3, Kzwgল্লা | D8: 12 | E8: =C8+D8 -> 12 | H8: 2 | I8: =G8+H8 -> 2
A9: 4 | B9: চৌদ্দগ্রাম বিদ্যুৎ সরবরাহ | D9: 1 | E9: 1
A10: 5 | B10: Pvu`cyi 150 †gtIt we`y¨r †K›`ª | D10: 2 | E10: =C10+D10 -> 2 | I10: =G10+H10 -> 0
A11: 6 | B11: বিক্রয় ও বিতরন বিভাগ- চাঁদপুর | C11: 1 | D11: 14 | E11: =C11+D11 -> 15 | F11: 3 | G11: 1 | I11: =G11+H11 -> 1
A12: 7 | B12: বিক্রয় ও বিতরন বিভাগ- নোয়াখালী | C12: 2 | D12: 16 | E12: =C12+D12 -> 18 | I12: =G12+H12 -> 0
A13: 8 | B13: jÿxcyi we`y¨r mieivn | C13: 2 | D13: 8 | E13: =C13+D13 -> 10 | I13: =G13+H13 -> 0
A14: 9 | B14: †PŠgynbx we`y¨r mieivn | D14: 7 | E14: =C14+D14 -> 7 | I14: =G14+H14 -> 0
A15: 10 | B15: বিক্রয় ও বিতরন বিভাগ- ফেনী | C15: 2 | D15: 24 | E15: =C15+D15 -> 26 | F15: 3 | G15: 1 | H15: 3 | I15: =G15+H15 -> 4
A16: 11 | B16: বিক্রয় ও বিতরন বিভাগ- 1, বি,বাড়িয়া | C16: 3 | D16: 11 | E16: =C16+D16 -> 14 | I16: =G16+H16 -> 0
A17: 12 | B17: বিক্রয় ও বিতরন বিভাগ- 2, বি,বাড়িয়া | D17: 3 | E17: =C17+D17 -> 3 | F17: 2 | G17: 2 | I17: =G17+H17 -> 2
A18: 13 | B18: বিতরণ ব্যবস্থা উন্নয়ন প্রকল্প, কুমিল্লা জোন | D18: 18 | E18: =C18+D18 -> 18 | F18: 8 | G18: 4 | H18: 4 | I18: =G18+H18 -> 8
A19: 14 | B19: হাতিয়া নিঝুমদ্বীপ শতভvগ বিদ্যূতায়ন প্রকল্প | C19: 3 | D19: 16 | E19: =C19+D19 -> 19 | H19: 8 | I19: =G19+H19 -> 8
B20: ‡gvU | C20: =SUM(C6:C19) -> 15 | D20: =SUM(D6:D19) -> 173 | E20: =C20+D20 -> 188 | F20: =SUM(F6:F19) -> 20 | G20: =SUM(G6:G19) -> 11 | H20: =SUM(H6:H19) -> 23 | I20: =G20+H20 -> 34

Sheet Summary_Sylhet
A1: সরকারি অডিট আপত্তির হালনাগাদ তথ্য
A2: সিলেট জোন 31-05-2026 পর্যন্ত
A3: ক্রt নং | B3: দপ্তরের নাম | C3: সাধারণ (Non SFI) আপত্তি | D3: অগ্রীম (SFI) আপত্তি | E3: মোট আপত্তি | F3: ত্রি-পক্ষীয় সভায় আলোচনা | G3: ত্রি-পক্ষীয় সভায় সুপারিশ | H3: ব্রডসীট জবাব প্রেরণ | I3: নিষ্পত্তির জন্য সুপারিশকৃত
A4: 1 | B4: 2 | C4: 3 | D4: 4 | E4: 5(3+4) | F4: 6 | G4: 7 | H4: 8 | I4: 9(7+8)
A5: 1 | B5: নির্বাহী প্রকৌশলী, বিক্রয় ও বিতরণ বিভাগ-১, বিউবো, সিলেট | C5: 7 | D5: 11 | E5: =C5+D5 -> 18 | F5: 4 | G5: 2 | H5: 5 | I5: =G5+H5 -> 7
A6: 2 | B6: নির্বাহী প্রকৌশলী, বিক্রয় ও বিতরণ বিভাগ-২, বিউবো, সিলেট | C6: 3 | D6: 7 | E6: =C6+D6 -> 10 | F6: 2 | G6: 1 | H6: 0 | I6: =G6+H6 -> 1
A7: 3 | B7: নির্বাহী প্রকৌশলী, বিক্রয় ও বিতরণ বিভাগ-৩, বিউবো, সিলেট | C7: 4 | D7: 8 | E7: =C7+D7 -> 12 | F7: 0 | G7: 0 | H7: 5 | I7: =G7+H7 -> 5
A8: 4 | B8: নির্বাহী প্রকৌশলী, বিক্রয় ও বিতরণ বিভাগ-৪, বিউবো, সিলেট | C8: 2 | D8: 3 | E8: =C8+D8 -> 5 | F8: 3 | G8: 1 | H8: 0 | I8: =G8+H8 -> 1
A9: 5 | B9: নির্বাহী প্রকৌশলী, বিক্রয় ও বিতরণ বিভাগ-৫, বিউবো, সিলেট | C9: 5 | D9: 9 | E9: =C9+D9 -> 14 | F9: 2 | G9: 0 | H9: 4 | I9: =G9+H9 -> 4
A10: 6 | B10: নির্বাহী প্রকৌশলী, বিক্রয় ও বিতরণ বিভাগ, বিউবো, সুনামগঞ্জ | C10: 4 | D10: 5 | E10: =C10+D10 -> 9 | F10: 5 | G10: 0 | H10: 0 | I10: =G10+H10 -> 0
A11: 7 | B11: নির্বাহী প্রকৌশলী, বিক্রয় ও বিতরণ বিভাগ, ছাতক, সুনামগঞ্জ। | C11: 2 | D11: 6 | E11: =C11+D11 -> 8 | F11: 6 | G11: 2 | H11: 0 | I11: =G11+H11 -> 2
A12: 8 | B12: নির্বাহী প্রকৌশলী, বিতরণ বিভাগ, বিউবো, মৌলভীবাজার | C12: 4 | D12: 15 | E12: =C12+D12 -> 19 | F12: 3 | G12: 2 | H12: 3 | I12: =G12+H12 -> 5
A13: 9 | B13: নির্বাহী প্রকৌশলী, বিক্রয় ও বিতরণ বিভাগ, কুলাউড়া, বিউবো, মৌলভীবাজার | C13: 4 | D13: 3 | E13: =C13+D13 -> 7 | F13: 2 | G13: 0 | H13: 0 | I13: =G13+H13 -> 0
A14: 10 | B14: নির্বাহী প্রকৌশলী, বিক্রয় ও বিতরণ বিভাগ, বিউবো, হবিগঞ্জ | C14: 4 | D14: 6 | E14: =C14+D14 -> 10 | F14: 6 | G14: 1 | H14: 0 | I14: =G14+H14 -> 1
A15: 11 | B15: ব্যবস্থাপক, ফেঞ্চুগঞ্জ ৯০ মেঃ ওঃ কম্বাইন্ড সাইকেল বিদ্যুৎ কেন্দ্র, বিউবো, ফেঞ্চুগঞ্জ, সিলেট | C15: 0 | D15: 1 | E15: =C15+D15 -> 1 | F15: 0 | G15: 0 | H15: 0 | I15: =G15+H15 -> 0
A16: 12 | B16: ব্যবস্থাপক, শাহ্‌জীবাজার বিদ্যুৎ কেন্দ্র, বিউবো, হবিগঞ্জ | C16: 0 | D16: 1 | E16: =C16+D16 -> 1 | F16: 0 | G16: 0 | H16: 0 | I16: =G16+H16 -> 0
... A21: 17 | B21: প্রধান প্রকৌশলী, সিলেট ২২৫ মেঃ ওঃ কম্বাইণ্ড সাইকেল পাওয়ার প্ল্যান্ট, বিউবো, কুমারগাও, সিলেট। | C21: 0 | D21: 7 | E21: =C21+D21 -> 7 | F21: 0 | G21: 0 | H21: 7 | I21: =G21+H21 -> 7
B22: মোট | C22: =SUM(C5:C21) -> 49 | D22: =SUM(D5:D21) -> 118 | E22: =SUM(E5:E21) -> 167 | F22: =SUM(F5:F21) -> 38 | G22: =SUM(G5:G21) -> 10 | H22: =SUM(H5:H21) -> 45 | I22: =SUM(I5:I21) -> 55

Sheet Summary_FAPAD
B1: বাংলাদেশ বিদ্যুৎ উন্নয়ন বোর্ড
B2: অনিষ্পন্ন অডিট আপত্তির প্রতিবেদন
B3: ফাপাড(১৭-০৬-২০২৬ খ্রি.)
A4: ক্র:নং | B4: দপ্তরের নাম | C4: সাধারণ | D4: অগ্রিম | E4: মোট | F4: ত্রিপক্ষীয়/দ্বিপক্ষীয় সভায় আলোচনা | G4: ত্রিপক্ষীয়/দ্বিপক্ষীয় সভায় সুপারিশ | H4: ব্রডশিট জবাব প্রেরণ | I4: নিষ্পত্তির সুপারিশ
A5: 1 | B5: 2 | C5: 3 | D5: 4 | E5: 5 | F5: 6 | G5: 7 | H5: 8 | I5: ৯=৭+৮
A6: 1 | B6: ১৬ শহর বিদ্যুৎ বিতরণ প্রকল্প | D6: 4 | E6: =SUM(C6:D6) -> 4
A7: 2 | B7: ইলেক্ট্রিফিকেশন এট ভাসানচর অফ নোয়াখালী ডিস্ট্রিক্ট প্রজেক্ট | C7: 4 | E7: 4 | H7: 4
A8: 3 | B8: ২১০ মেঃওঃ সিদ্দিরগঞ্জ থারমাল পাওয়ার ষ্টেশন প্রকল্প | D8: 2 | E8: =SUM(C8:D8) -> 2 | H8: 2
A9: 4 | B9: ৯ শহর বিদ্যুৎ বিতরন প্রকল্প | D9: =6-1 -> 5 | E9: =SUM(C9:D9) -> 5 | F9: 5
A10: 5 | B10: ঘোড়াশাল ৩য় ইউনিট রি-পাওয়ারিং প্রকল্প | C10: 3 | D10: 10 | E10: =SUM(C10:D10) -> 13 | H10: 13
A11: 6 | B11: কনভারশন অব বাঘাবাড়ী ১০০ মেঃওঃ টু ১৫০ মেঃওঃ সিসিপিপি প্রজেক্ট | C11: 1 | E11: =SUM(C11:D11) -> 1 | H11: 1
A12: 7 | B12: কর্ণফুলী পানি বিদ্যুৎ কেন্দ্র (ইউনিট- ৪ ও ৫) পুনর্বাসন প্রকল্প | D12: 1 | E12: =SUM(C12:D12) -> 1
A13: 8 | B13: কর্ণফুলী পানি বিদ্যুৎ কেন্দ্র পুনর্বাসন প্রকল্প (ইউনিট-৩) | D13: 1 | E13: =SUM(C13:D13) -> 1
A14: 9 | B14: ঘোড়াশাল ৩৬৫ মেঃওঃ সিসিপিপি নির্মাণ প্রকল্প | C14: 4 | D14: 2 | E14: =SUM(C14:D14) -> 6 | F14: 4 | H14: 2
A15: 10 | B15: ঘোড়াশাল ৪র্থ ইউনিট রি-পাওয়ারিং প্রকল্প | D15: 1 | E15: =SUM(C15:D15) -> 1 | H15: 1
A16: 11 | B16: চাঁপাইনবাবগঞ্জ ১০০ মেঃওঃ বিদ্যুৎ কেন্দ্র নির্মান প্রকল্প | C16: =8-2 -> 6 | D16: 2 | E16: =SUM(C16:D16) -> 8 | F16: 1 | H16: 7
A17: 12 | B17: টেকনিক্যাল এসিসট্যান্স ফর দ্যা করপোরেশন অব বিপিডিবিস | D17: 4 | E17: =SUM(C17:D17) -> 4 | H17: 4
A18: 13 | B18: প্রি-পেমেন্ট মিটারিং প্রকল্প, বিতরন কুমিল্লা ও ময়মনসিংহ অঞ্চল | C18: 5 | D18: 16 | E18: =SUM(C18:D18) -> 21 | F18: 6 | H18: 12
A19: 14 | B19: বড়পুকুরিয়া ৩০০ মেঃওঃ কয়লাভিত্তিক তাপ বিদ্যুৎ কেন্দ্র নির্মাণ প্রকল্প | D19: 9 | E19: =SUM(C19:D19) -> 9 | H19: 2
A20: 15 | B20: বিবিয়ানা -৩, ৪০০ মেঃওঃ সিসিপিপি নিমার্ণ প্রকল্প | C20: 3 | D20: 3 | E20: =SUM(C20:D20) -> 6 | F20: 5 | H20: 2
A21: 16 | B21: বৃহত্তর চট্টগ্রাম বিদ্যুৎ বিতরণ প্রকল্প (ফেজ-৩) | D21: 2 | E21: =SUM(C21:D21) -> 2
A22: 17 | B22: বৃহত্তর চট্টগ্রাম বিদ্যুৎ বিতরণ প্রকল্প-ষ্কেডা পূর্নবাসন | D22: 1 | E22: =SUM(C22:D22) -> 1 | F22: 1
A23: 18 | B23: ভোলা ২২৫ মেঃওঃ কঃসাঃ বিঃকেঃ নির্মাণ প্রকল্প | C23: 4 | D23: 2 | E23: =SUM(C23:D23) -> 6 | F23: 4 | H23: 1
A24: 19 | B24: শিকলবাহা ২২৫ মেঃওঃ ডুয়েল ফুয়েল সিসিপিপি নির্মাণ প্রকল্প | D24: 9 | E24: =SUM(C24:D24) -> 9 | H24: 9
A25: 20 | B25: সেন্ট্রল জোন পাওয়ার ডিষ্ট্রিবিউশন প্রজেক্ট | D25: =9-7 -> 2 | E25: =SUM(C25:D25) -> 2 | H25: 2
A26: 21 | B26: সোলার ষ্ট্রিট লাইটিং প্রেগ্রাম ইন সিটি কর্পোরেশন | C26: 1 | D26: 1 | E26: =SUM(C26:D26) -> 2 | H26: 2
A27: 22 | B27: হরিপুর বিদ্যুৎ কেন্দ্র-১, ২ ও ৩ ইউনিট রেনোভেশন প্রকল্প | D27: 1 | E27: =SUM(C27:D27) -> 1 | H27: 1
A28: 23 | B28: সৈয়দপুর ১৫০ মে: ও: +- ১০% সিম্পল সাইকেল (এইচএসডি ভিত্তিক) বিদ্যুৎ কেন্দ্র নির্মান প্রকল্প | C28: 6 | D28: 6 | E28: 12 | H28: 11
A29: 24 | B29: খুলনা ৩৩০ মেঃওঃ ডুয়েল ফুয়েল সিসিপিপি নির্মাণ প্রকল্প, বিউবো, খুলনা | C29: 1 | E29: 1 | H29: 1
A30: 25 | B30: স্মাট প্রি-পেমেন্ট মিটিারিং প্রজেক্ট ইন ডিস্ট্রিবিউশন জোনস অফ বিপিডিবি, বিউবো, ঢাকা। | C30: 7 | D30: 7 | E30: =SUM(C30+D30) -> 14 | H30: 14
B31: মোট | C31: =SUM(C6:C30) -> 45 | D31: =SUM(D6:D30) -> 91 | E31: =SUM(C31+D31) -> 136 | F31: =SUM(F6:F30) -> 26 | G31: =SUM(G6:G27) -> 0 | H31: =SUM(H6:H30) -> 91

Sheet Summary_Dhaka
A1: বাংলাদেশ বিদ্যুৎ উন্নয়ন বোর্ড অডিট অধিদপ্তর সরকারী অনিষ্পন্ন অডিট আপত্তির প্রতিবেদন ঢাকা জোন 31/05/2026খ্রি. পর্যন্ত
A2: ক্রমিক নং | B2: দপ্তরের নাম | C2: NON SFI (সাধারণ) | D2: SFI(অগ্রিম) | E2: মোট | F2: ত্রিপক্ষীয় সভায় আলোচনা (SFI) | G2: ত্রিপক্ষীয় সভার সুপারিশ (SFI) | H2: ব্রডশীট জবাব প্রেরণ (SFI) | I2: নিষ্পত্তির জন্য সুপারিশ
A3: 1 | B3: 2 | C3: 3 | D3: 4 | E3: 5=(3+4) | F3: 6 | G3: 7 | H3: 8 | I3: 9=(7+8)
A4: 1 | B4: ব্যবস্থাপক, সিদ্ধিরগঞ্জ বিদুৎ কেন্দ্র,বিউবো,নারায়নগঞ্জ | D4: 6 | E4: =C4+D4 -> 6 | F4: 4 | G4: 3 | I4: =G4+H4 -> 3
A5: 2 | B5: কেন্দ্রীয় সচিবালয়, বিউবো, ঢাকা। | C5: 4 | D5: 9 | E5: =C5+D5 -> 13 | F5: 3 | H5: 3 | I5: =G5+H5 -> 3
A6: 3 | B6: পরিচালক, সম্পত্তি ও যানবাহন পরিদপ্তর, বিউবো, ঢাকা। | C6: 6 | D6: 51 | E6: =C6+D6 -> 57 | F6: 12 | G6: 8 | H6: 5 | I6: =G6+H6 -> 13
A7: 4 | B7: পরিচালক, ক্রয় পরিদপ্তর, বিউবো, ঢাকা। | C7: 8 | D7: 38 | E7: =C7+D7 -> 46 | F7: 18 | G7: 9 | H7: 18 | I7: =G7+H7 -> 27
A8: 5 | B8: নির্বাহী প্রকৌশলী, পূর্ত নির্মাণ বিভাগ-১, বিউবো, ঢাকা। | C8: 2 | D8: 9 | E8: =C8+D8 -> 11 | F8: 13 | G8: 9 | H8: 7 | I8: =G8+H8 -> 16
A9: 6 | B9: নির্বাহী প্রকৌশলী, পূর্ত নির্মাণ বিভাগ-২, বিউবো, ঢাকা। | C9: 6 | D9: 8 | E9: =C9+D9 -> 14 | F9: 12 | G9: 8 | H9: 5 | I9: =G9+H9 -> 13
A10: 7 | B10: পরিচালক, বৈদ্যুতিক সরঞ্জাম পরিদপ্তর বিউবো, ঢাকা। | D10: 2 | E10: =C10+D10 -> 2 | F10: 1 | I10: =G10+H10 -> 0
A11: 8 | B11: প্রধান প্রকৌশলী, প্রাইভেট জেনারেশন, বিউবো, ঢাকা। | C11: 2 | D11: 21 | E11: =C11+D11 -> 23 | H11: 19 | I11: =G11+H11 -> 19
A12: 9 | B12: প্রধান প্রকৌশলী, ঘোড়াশাল বিদ্যুৎ কেন্দ্র, বিউবো, পলাশ, নরসিংদী | D12: 5 | E12: =C12+D12 -> 5 | F12: 1 | G12: 1 | I12: =G12+H12 -> 1
A13: 10 | B13: ১০০ মেঃ ওঃ হরিপুর বিদ্যুৎ কেন্দ্র, বিউবো, নারায়নগঞ্জ। | D13: 2 | E13: =C13+D13 -> 2 | F13: 1 | G13: 1 | I13: =G13+H13 -> 1
A14: 11 | B14: নির্বাহী প্রকৌশলী, পিসিপোল বিভাগ,আরিচা, বিউবো, মানিকগঞ্জ | C14: 5 | D14: 27 | E14: =C14+D14 -> 32 | F14: 28 | G14: 20 | H14: 9 | I14: =G14+H14 -> 29
A15: 12 | B15: কেন্দ্রীয় মেরামত কারখানা, বিউবো, টংগী, গাজীপুর (সিইআরএস) | D15: 3 | E15: =C15+D15 -> 3 | F15: 3 | G15: 1 | I15: =G15+H15 -> 1
A16: 13 | B16: আঞ্চলিক মেরামত কারখানা, বিউবো, টংগী,গাজীপুর। | C16: 2 | D16: 2 | E16: =C16+D16 -> 4 | I16: =G16+H16 -> 0
A17: 14 | B17: উপ-পরিচালক, আঞ্চলিক, প্রশিক্ষণ কেন্দ্র, বিউবো, টঙ্গী, গাজীপুর। | D17: 1 | E17: =C17+D17 -> 1 | I17: =G17+H17 -> 0
A18: 15 | B18: কেন্দ্রীয়ভান্ডার, বিউবো, টঙ্গী, গাজীপুর | C18: 2 | D18: 3 | E18: =C18+D18 -> 5 | I18: =G18+H18 -> 0
A19: 16 | B19: প্রধান প্রকৌশলী, উৎপাদন, বিউবো, ঢাকা | C19: 1 | D19: 2 | E19: =C19+D19 -> 3 | F19: 2 | G19: 1 | H19: 3 | I19: =G19+H19 -> 4
A20: 17 | B20: আইপিপি সেল-০২, বিউবো, ঢাকা | C20: 3 | D20: 5 | E20: =C20+D20 -> 8 | I20: =G20+H20 -> 0
A21: 18 | B21: আইপিপি সেল-০১, বিউবো, ঢাকা | D21: 1 | E21: =C21+D21 -> 1 | F21: 1 | H21: 4 | I21: =G21+H21 -> 4
A22: 19 | B22: পরিচালক, কর্মচারী পরিদপ্তর, বিউবো, ঢাকা। | C22: 1 | D22: 4 | E22: =C22+D22 -> 5 | F22: 4 | G22: 2 | H22: 4 | I22: =G22+H22 -> 6
A23: 20 | B23: মহাব্যবস্থাপক, বাণিজ্যিক পরিচালন, বিউবো, ঢাকা | D23: 1 | E23: =C23+D23 -> 1 | I23: =G23+H23 -> 0
A24: 21 | B24: প্রকল্প পরিচালক (প্রধান প্রকৌশলী), জি টি পি- এস-ই-প্রকল্প, ২১০ মেঃওঃ ঘোড়াশাল তাপ বিদ্যুৎ কেন্দ্র স¤ক্স্রসারণ প্রকল্প, বিউবো, পলাশ, ঘোড়াশাল। | D24: 1
A25: মোট | C25: =SUM(C4:C24) -> 42 | D25: =SUM(D4:D24) -> 201 | E25: =SUM(E4:E24) -> 242 | F25: =SUM(F4:F24) -> 103 | G25: =SUM(G4:G24) -> 63 | H25: =SUM(H4:H24) -> 77 | I25: =SUM(I4:I24) -> 140
